<?xml version="1.0"?>
<sdf version='1.10'>
    <world name="car_world">
        <physics name="1ms" type="ode">
            <max_step_size>0.001</max_step_size>
            <real_time_factor>1.0</real_time_factor>
        </physics>

        <plugin filename="gz-sim-physics-system" name="gz::sim::systems::Physics"/>
        <plugin filename="gz-sim-user-commands-system" name="gz::sim::systems::UserCommands"/>
        <plugin filename="gz-sim-scene-broadcaster-system" name="gz::sim::systems::SceneBroadcaster"/>
        <plugin filename="gz-sim-sensors-system" name="gz::sim::systems::Sensors"/>

        <light type="directional" name="sun">
            <cast_shadows>true</cast_shadows>
            <pose>0 0 10 0 0 0</pose>
            <diffuse>0.8 0.8 0.8 1</diffuse>
            <specular>0.2 0.2 0.2 1</specular>
            <attenuation>
                <range>1000</range>
                <constant>0.9</constant>
                <linear>0.01</linear>
                <quadratic>0.001</quadratic>
            </attenuation>
            <direction>-0.5 0.1 -0.9</direction>
        </light>

        <model name="ground_plane">
            <static>true</static>
            <link name="link">
                <collision name="collision">
                    <geometry>
                        <plane>
                            <normal>0 0 1</normal>
                        </plane>
                    </geometry>
                </collision>
                <visual name="visual">
                    <geometry>
                        <plane>
                            <normal>0 0 1</normal>
                            <size>100 100</size>
                        </plane>
                    </geometry>
                    <material>
                        <ambient>0.8 0.8 0.8 1</ambient>
                        <diffuse>0.8 0.8 0.8 1</diffuse>
                        <specular>0.8 0.8 0.8 1</specular>
                    </material>
                </visual>
            </link>
        </model>

        <model name="my_robot">
            <plugin filename="gz-sim-diff-drive-system" name="gz::sim::systems::DiffDrive">
                <left_joint>left_wheel_hinge</left_joint>
                <right_joint>right_wheel_hinge</right_joint>
                <wheel_separation>0.26</wheel_separation>
                <wheel_radius>0.1</wheel_radius>
                <odom_publish_frequency>50</odom_publish_frequency>
                <topic>cmd_vel</topic>
            </plugin>

            <static>false</static>

            <link name="chassis">
                <pose>0 0 0.1 0 0 0</pose>
                <inertial>
                    <mass>5.0</mass>
                    <inertia>
                        <ixx>0.02</ixx> <ixy>0.0</ixy> <ixz>0.0</ixz>
                        <iyy>0.02</iyy> <iyz>0.0</iyz> <izz>0.04</izz>
                    </inertia>
                </inertial>

                <collision name="collision">
                    <geometry>
                        <box>
                            <size>0.4 0.2 0.1</size>
                        </box>
                    </geometry>
                </collision>

                <visual name="visual">
                    <geometry>
                        <box>
                            <size>0.4 0.2 0.1</size>
                        </box>
                    </geometry>
                </visual>

                <collision name="castor_collision">
                    <pose>-0.15 0 -0.05 0 0 0</pose>
                    <geometry>
                        <sphere>
                            <radius>0.05</radius>
                        </sphere>
                    </geometry>
                    <surface>
                        <friction>
                            <ode>
                                <mu>0.1</mu>
                                <mu2>0.1</mu2>
                            </ode>
                        </friction>
                    </surface>
                </collision>

                <visual name="castor_visual">
                    <pose>-0.15 0 -0.05 0 0 0</pose>
                    <geometry>
                        <sphere>
                            <radius>0.05</radius>
                        </sphere>
                    </geometry>
                </visual>

                <sensor name="lidar" type="gpu_lidar">
                    <!-- pose: x y z R P Y  (in chassis frame) -->
                    <pose>0 0 0.15 0 0 0</pose>
                    <update_rate>5</update_rate>
                    <always_on>true</always_on>
                    <visualize>true</visualize>

                    <lidar>
                        <scan>
                        <horizontal>
                            <samples>720</samples>
                            <min_angle>-3.14159</min_angle>
                            <max_angle> 3.14159</max_angle>
                        </horizontal>
                        <!-- 2‑D → one vertical layer -->
                        <vertical>
                            <samples>1</samples>
                            <min_angle>0</min_angle>
                            <max_angle>0</max_angle>
                        </vertical>
                        </scan>
                        <range>
                        <min>0.12</min>
                        <max>12.0</max>
                        <resolution>0.01</resolution>
                        </range>
                    </lidar>
                    <topic>/scan</topic> 
                </sensor>

            </link>

            <link name="left_wheel">
                <pose>0.1 0.13 0.1 0 1.5707 1.5707</pose>
                <inertial>
                    <mass>1.0</mass>
                    <inertia>
                        <ixx>0.005</ixx> <ixy>0.0</ixy> <ixz>0.0</ixz>
                        <iyy>0.005</iyy> <iyz>0.0</iyz>
                        <izz>0.01</izz>
                    </inertia>
                </inertial>
                <collision name="left_wheel_collision">
                    <geometry>
                        <cylinder>
                            <radius>0.1</radius>
                            <length>0.05</length>
                        </cylinder>
                    </geometry>
                    <surface>
                        <friction>
                            <ode>
                                <mu>0.5</mu>
                                <mu2>0.1</mu2>
                            </ode>
                        </friction>
                    </surface>
                </collision>
                <visual name="visual">
                    <geometry>
                        <cylinder>
                            <radius>0.1</radius>
                            <length>0.05</length>
                        </cylinder>
                    </geometry>
                </visual>
            </link>

            <link name="right_wheel">
                <pose>0.1 -0.13 0.1 0 1.5707 1.5707</pose>
                <inertial>
                    <mass>1.0</mass>
                    <inertia>
                        <ixx>0.005</ixx> <ixy>0.0</ixy> <ixz>0.0</ixz>
                        <iyy>0.005</iyy> <iyz>0.0</iyz>
                        <izz>0.01</izz>
                    </inertia>
                </inertial>
                <collision name="right_wheel_collision">
                    <geometry>
                        <cylinder>
                            <radius>0.1</radius>
                            <length>0.05</length>
                        </cylinder>
                    </geometry>
                    <surface>
                        <friction>
                            <ode>
                                <mu>0.5</mu>
                                <mu2>0.1</mu2>
                            </ode>
                        </friction>
                    </surface>
                </collision>
                <visual name="visual">
                    <geometry>
                        <cylinder>
                            <radius>0.1</radius>
                            <length>0.05</length>
                        </cylinder>
                    </geometry>
                </visual>
            </link>

            <joint type="revolute" name="left_wheel_hinge">
                <pose>0 0 -0.03 0 0 0</pose>
                <child>left_wheel</child>
                <parent>chassis</parent>
                <axis>
                    <xyz>0 0 1</xyz>
                </axis>
            </joint>

            <joint type="revolute" name="right_wheel_hinge">
                <pose>0 0 0.03 0 0 0</pose>
                <child>right_wheel</child>
                <parent>chassis</parent>
                <axis>
                    <xyz>0 0 1</xyz>
                </axis>
            </joint>
        </model>
    </world>
</sdf>
